Workbook

Sheet Inputs & Assumptions
A2: Company Name | B2: Jyothy Labs Ltd
A3: Valuation Date | B3: 46276 | F3: Segment Growth Estimate | H3: %
A4: Latest Financial Year End | B4: 46112 | F4: A. | G4: Fabric Care
A5: Latest Financial Reporting Date | B5: 46203 | G5: Volume Growth for next year | H5: 0.115
A6: Next Financial Year End | B6: 46477 | C6: Start Date | D6: End Date | G6: Volume Growth for year 2-5 | H6: 0.1
A7: Latest Reporting Period | B7: Q1 FY27 | C7: 46113 | D7: 46203 | G7: Price/Mix for next year | H7: 0.04
A8: Next Reporting Period | B8: Q2 FY27 | C8: 46204 | D8: 46295 | G8: Price/Mix for year 2-5 | H8: 0.02
A9: Share price on valuation date | B9: 195 | G9: Value growth for year 6-10 | H9: 0.08
A10: No. of shares outstanding (Crores) | B10: 36.72 | F10: B. | G10: Home Care
A11: Market capitalization (Rs.Crores) | B11: =B9*B10 -> 7160.4 | G11: Volume Growth for next year | H11: -0.13
A12: Cash & equivalents | B12: 816 | G12: Volume Growth for year 2-5 | H12: 0.12
A13: Short-term borrowings | B13: 0 | G13: Price/Mix for next year | H13: 0.04
A14: Long-term borrowings | B14: 0 | G14: Price/Mix for year 2-5 | H14: 0.01
A15: Current portion of borrowings | B15: 0 | G15: Value growth for year 6-10 | H15: 0.09
A16: Current lease liabilities | B16: 25.13 | F16: C. | G16: Personal Care
A17: Non-current lease liabilities | B17: 26.45 | G17: Volume Growth for next year | H17: -0.05
G18: Volume Growth for year 2-5 | H18: 0.08
A19: EBIT Margin for next year | B19: 0.072 | G19: Price/Mix for next year | H19: 0.09
A20: EBIT Margin for year 2 | B20: 0.1175 | G20: Price/Mix for year 2-5 | H20: 0.01
A21: EBIT Margin for year 3-5 | B21: 0.15 | G21: Value growth for year 6-10 | H21: 0.05
A22: EBIT Margin for year 6-10 | B22: 0.19
A23: Terminal EBIT Margin | B23: 0.17
A24: Gross Capex as % of Revenue | B24: 0.022
A25: PP&E Depreciation as % of Revenue | B25: 0.011
A26: Working Capital Days | B26: 15
A27: Terminal Growth Rate | B27: 0.055
A28: Terminal ROC | B28: 0.14
A29: Cost of Capital | B29: ='Cost of Capital'!D34 -> 0.10453928
A30: Tax Rate | B30: 0.26

Sheet Revenue Build
B3: Segments | D3: =YEAR('Inputs & Assumptions'!B4) -> 2026 | E3: =D3+1 -> 2027 | F3: =E3+1 -> 2028 | G3: =F3+1 -> 2029 | H3: =G3+1 -> 2030 | I3: =H3+1 -> 2031 | J3: =I3+1 -> 2032 | K3: =J3+1 -> 2033 | L3: =K3+1 -> 2034 | ... N3: =M3+1 -> 2036
B4: A. Fabric Care
C5: Revenue | D5: 1346 | E5: =D5*(1+E8) -> 1560.8216 | F5: =E5*(1+F8) -> 1777.7085 | G5: =F5*(1+G8) -> 2004.5868 | H5: =G5*(1+H8) -> 2237.9287 | I5: =H5*(1+I8) -> 2473.5728 | J5: =I5*(1+J8) -> 2725.4257 | K5: =J5*(1+K8) -> 2973.042 | L5: =K5*(1+L8) -> 3210.8853 | ... N5: =M5*(1+N8) -> 3634.4899
C6: Volume Growth | D6: 0.095 | E6: ='Inputs & Assumptions'!H5 -> 0.115 | F6: =(1+'Inputs & Assumptions'!$H$6)*EXP(0.01*((4+1)/2-COLUMNS('Revenue Build'!$F$6:F6)))-1 -> 0.11662437 | G6: =(1+'Inputs & Assumptions'!$H$6)*EXP(0.01*((4+1)/2-COLUMNS('Revenue Build'!$F$6:G6)))-1 -> 0.10551377 | H6: =(1+'Inputs & Assumptions'!$H$6)*EXP(0.01*((4+1)/2-COLUMNS('Revenue Build'!$F$6:H6)))-1 -> 0.094513727 | I6: =(1+'Inputs & Assumptions'!$H$6)*EXP(0.01*((4+1)/2-COLUMNS('Revenue Build'!$F$6:I6)))-1 -> 0.083623134 | J6: - | K6: - | L6: - | M6: - | N6: -
C7: Price/Mix | D7: -0.014 | E7: ='Inputs & Assumptions'!H7 -> 0.04 | F7: ='Inputs & Assumptions'!$H$8 -> 0.02 | G7: ='Inputs & Assumptions'!$H$8 -> 0.02 | H7: ='Inputs & Assumptions'!$H$8 -> 0.02 | I7: ='Inputs & Assumptions'!$H$8 -> 0.02 | J7: - | K7: - | L7: - | M7: - | N7: -
C8: Value Growth | D8: 0.081 | E8: =(1+E6)*(1+E7)-1 -> 0.1596 | F8: =(1+F6)*(1+F7)-1 -> 0.13895686 | G8: =(1+G6)*(1+G7)-1 -> 0.12762405 | H8: =(1+H6)*(1+H7)-1 -> 0.116404 | I8: =(1+I6)*(1+I7)-1 -> 0.1052956 | J8: =(1+'Inputs & Assumptions'!$H$9)*EXP(0.01*((5+1)/2-COLUMNS('Revenue Build'!$J$8:J8)))-1 -> 0.10181745 | K8: =(1+'Inputs & Assumptions'!$H$9)*EXP(0.01*((5+1)/2-COLUMNS('Revenue Build'!$J$8:K8)))-1 -> 0.09085418 | L8: =(1+'Inputs & Assumptions'!$H$9)*EXP(0.01*((5+1)/2-COLUMNS('Revenue Build'!$J$8:L8)))-1 -> 0.08 | M8: =(1+'Inputs & Assumptions'!$H$9)*EXP(0.01*((5+1)/2-COLUMNS('Revenue Build'!$J$8:M8)))-1 -> 0.06925382 | N8: =(1+'Inputs & Assumptions'!$H$9)*EXP(0.01*((5+1)/2-COLUMNS('Revenue Build'!$J$8:N8)))-1 -> 0.058614567
B9: B. Home Care
C10: Revenue | D10: 1277 | E10: =D10*(1+E13) -> 1155.4296 | F10: =E10*(1+F13) -> 1326.7751 | G10: =F10*(1+G13) -> 1508.371 | H10: =G10*(1+H13) -> 1697.7592 | I10: =H10*(1+I13) -> 1891.9126 | J10: =I10*(1+J13) -> 2103.8437 | K10: =J10*(1+K13) -> 2316.2365 | L10: =K10*(1+L13) -> 2524.6978 | ... N10: =M10*(1+N13) -> 2910.9421
C11: Volume Growth | D11: 0.034 | E11: ='Inputs & Assumptions'!H11 -> -0.13 | F11: =(1+'Inputs & Assumptions'!$H$12)*EXP(0.01*((4+1)/2-COLUMNS('Revenue Build'!$F$11:F11)))-1 -> 0.13692663 | G11: =(1+'Inputs & Assumptions'!$H$12)*EXP(0.01*((4+1)/2-COLUMNS('Revenue Build'!$F$11:G11)))-1 -> 0.12561402 | H11: =(1+'Inputs & Assumptions'!$H$12)*EXP(0.01*((4+1)/2-COLUMNS('Revenue Build'!$F$11:H11)))-1 -> 0.11441398 | I11: =(1+'Inputs & Assumptions'!$H$12)*EXP(0.01*((4+1)/2-COLUMNS('Revenue Build'!$F$11:I11)))-1 -> 0.10332537 | J11: - | K11: - | L11: - | M11: - | N11: -
C12: Price/Mix | D12: -0.047 | E12: ='Inputs & Assumptions'!H13 -> 0.04 | F12: ='Inputs & Assumptions'!$H$14 -> 0.01 | G12: ='Inputs & Assumptions'!$H$14 -> 0.01 | H12: ='Inputs & Assumptions'!$H$14 -> 0.01 | I12: ='Inputs & Assumptions'!$H$14 -> 0.01 | J12: - | K12: - | L12: - | M12: - | N12: -
C13: Value Growth | D13: -0.013 | E13: =(1+E11)*(1+E12)-1 -> -0.0952 | F13: =(1+F11)*(1+F12)-1 -> 0.1482959 | G13: =(1+G11)*(1+G12)-1 -> 0.13687016 | H13: =(1+H11)*(1+H12)-1 -> 0.12555812 | I13: =(1+I11)*(1+I12)-1 -> 0.11435863 | J13: =(1+'Inputs & Assumptions'!$H$15)*EXP(0.01*((5+1)/2-COLUMNS('Revenue Build'!$J$13:J13)))-1 -> 0.11201946 | K13: =(1+'Inputs & Assumptions'!$H$15)*EXP(0.01*((5+1)/2-COLUMNS('Revenue Build'!$J$13:K13)))-1 -> 0.10095468 | L13: =(1+'Inputs & Assumptions'!$H$15)*EXP(0.01*((5+1)/2-COLUMNS('Revenue Build'!$J$13:L13)))-1 -> 0.09 | M13: =(1+'Inputs & Assumptions'!$H$15)*EXP(0.01*((5+1)/2-COLUMNS('Revenue Build'!$J$13:M13)))-1 -> 0.079154319 | N13: =(1+'Inputs & Assumptions'!$H$15)*EXP(0.01*((5+1)/2-COLUMNS('Revenue Build'!$J$13:N13)))-1 -> 0.068416554
B14: C. Personal Care
C15: Revenue | D15: 321 | E15: =D15*(1+E18) -> 332.3955 | F15: =E15*(1+F18) -> 368.05666 | G15: =F15*(1+G18) -> 403.48861 | H15: =G15*(1+H18) -> 437.93025 | I15: =H15*(1+I18) -> 470.58237 | J15: =I15*(1+J18) -> 504.0932 | K15: =J15*(1+K18) -> 534.61739 | L15: =K15*(1+L18) -> 561.34826 | ... N15: =M15*(1+N18) -> 600.5956
C16: Volume Growth | D16: 0.016 | E16: ='Inputs & Assumptions'!H17 -> -0.05 | F16: =(1+'Inputs & Assumptions'!$H$18)*EXP(0.01*((4+1)/2-COLUMNS('Revenue Build'!$F$16:F16)))-1 -> 0.09632211 | G16: =(1+'Inputs & Assumptions'!$H$18)*EXP(0.01*((4+1)/2-COLUMNS('Revenue Build'!$F$16:G16)))-1 -> 0.085413523 | H16: =(1+'Inputs & Assumptions'!$H$18)*EXP(0.01*((4+1)/2-COLUMNS('Revenue Build'!$F$16:H16)))-1 -> 0.074613478 | I16: =(1+'Inputs & Assumptions'!$H$18)*EXP(0.01*((4+1)/2-COLUMNS('Revenue Build'!$F$16:I16)))-1 -> 0.063920895 | J16: - | K16: - | L16: - | M16: - | N16: -
C17: Price/Mix | D17: 0.036 | E17: ='Inputs & Assumptions'!H19 -> 0.09 | F17: ='Inputs & Assumptions'!$H$20 -> 0.01 | G17: ='Inputs & Assumptions'!$H$20 -> 0.01 | H17: ='Inputs & Assumptions'!$H$20 -> 0.01 | I17: ='Inputs & Assumptions'!$H$20 -> 0.01 | J17: - | K17: - | L17: - | M17: - | N17: -
C18: Value Growth | D18: 0.052 | E18: =(1+E16)*(1+E17)-1 -> 0.0355 | F18: =(1+F16)*(1+F17)-1 -> 0.10728533 | G18: =(1+G16)*(1+G17)-1 -> 0.096267658 | H18: =(1+H16)*(1+H17)-1 -> 0.085359612 | I18: =(1+I16)*(1+I17)-1 -> 0.074560104 | J18: =(1+'Inputs & Assumptions'!$H$21)*EXP(0.01*((5+1)/2-COLUMNS('Revenue Build'!$J$18:J18)))-1 -> 0.071211407 | K18: =(1+'Inputs & Assumptions'!$H$21)*EXP(0.01*((5+1)/2-COLUMNS('Revenue Build'!$J$18:K18)))-1 -> 0.060552675 | L18: =(1+'Inputs & Assumptions'!$H$21)*EXP(0.01*((5+1)/2-COLUMNS('Revenue Build'!$J$18:L18)))-1 -> 0.05 | M18: =(1+'Inputs & Assumptions'!$H$21)*EXP(0.01*((5+1)/2-COLUMNS('Revenue Build'!$J$18:M18)))-1 -> 0.039552325 | N18: =(1+'Inputs & Assumptions'!$H$21)*EXP(0.01*((5+1)/2-COLUMNS('Revenue Build'!$J$18:N18)))-1 -> 0.029208607
B19: Total Revenue | D19: =D5+D10+D15 -> 2944 | E19: =E5+E10+E15 -> 3048.6467 | F19: =F5+F10+F15 -> 3472.5402 | G19: =G5+G10+G15 -> 3916.4464 | H19: =H5+H10+H15 -> 4373.6182 | I19: =I5+I10+I15 -> 4836.0678 | J19: =J5+J10+J15 -> 5333.3625 | K19: =K5+K10+K15 -> 5823.8959 | ... N19: =N5+N10+N15 -> 7146.0276
B20: Revenue Growth | D20: 0.035 | E20: =(E19/D19)-1 -> 0.035545754 | F20: =(F19/E19)-1 -> 0.13904317 | G20: =(G19/F19)-1 -> 0.12783329 | H20: =(H19/G19)-1 -> 0.11673127 | I20: =(I19/H19)-1 -> 0.10573616 | J20: =(J19/I19)-1 -> 0.10283039 | K20: =(K19/J19)-1 -> 0.091974504 | L20: =(L19/K19)-1 -> 0.081223209 | ... N20: =(N19/M19)-1 -> 0.060030608

Sheet Cost of Capital
A2: EQUITY
A3: No. of Shares outstanding | B3: ='Inputs & Assumptions'!B10 -> 36.72
A4: Current Market Price per share | B4: ='Inputs & Assumptions'!B9 -> 195
A5: Market Value of Equity | B5: ='Inputs & Assumptions'!B11 -> 7160.4
A7: Risk-free rate | B7: 0.0696
A8: Levered Beta | B8: 0.51
A9: Equity Risk Premium | B9: 0.0692
A10: Cost of Equity | B10: =B7+(B8*B9) -> 0.104892
A12: DEBT
A13: Short-term borrowings | B13: ='Inputs & Assumptions'!B13 -> 0
A14: Long-term borrowings | B14: ='Inputs & Assumptions'!B14 -> 0
A15: Current portion of borrowings | B15: ='Inputs & Assumptions'!B15 -> 0
A16: Conventional Debt | B16: =SUM(B13:B15) -> 0
A18: Current lease liabilities | B18: ='Inputs & Assumptions'!B16 -> 25.13
A19: Non-current lease liabilities | B19: ='Inputs & Assumptions'!B17 -> 26.45
A20: Total Lease Debt | B20: =SUM(B18:B19) -> 51.58
A22: Total Debt | B22: =B16+B20 -> 51.58
A24: Tax Rate | B24: ='Inputs & Assumptions'!B30 -> 0.26
A25: Credit Rating | B25: CARE AA
A26: Risk-free rate | B26: =B7 -> 0.0696
A27: Default spread | B27: 0.0055
A28: Pre-tax Cost of Debt | B28: =B26+B27 -> 0.0751
A29: After-tax Cost of Debt | B29: =B28*(1-B24) -> 0.055574
A31: Capital | B31: Value | C31: Weight | D31: Cost
A32: Equity | B32: =B5 -> 7160.4 | C32: =B32/$B$34 -> 0.99284801 | D32: =B10 -> 0.104892
A33: Debt | B33: =B22 -> 51.58 | C33: =B33/$B$34 -> 0.0071519888 | D33: =B29 -> 0.055574
A34: Total Capital | B34: =SUM(B32:B33) -> 7211.98 | C34: =SUM(C32:C33) -> 1 | D34: =C32*D32+C33*D33 -> 0.10453928

Sheet Valuation
B2: (Rs. Crores) | C2: =YEAR('Inputs & Assumptions'!B4) -> 2026 | D2: =C2+1 -> 2027 | E2: =D2+1 -> 2028 | F2: =E2+1 -> 2029 | G2: =F2+1 -> 2030 | H2: =G2+1 -> 2031 | I2: =H2+1 -> 2032 | J2: =I2+1 -> 2033 | K2: =J2+1 -> 2034 | ... M2: =L2+1 -> 2036 | N2: Terminal Year | P2: (Rs. Crores) | Q2: Q1 FY26A | R2: Q2 FY26A | S2: Q3 FY26A | T2: Q4 FY26A | U2: Q1 FY27A | V2: Q2 FY27E | W2: Q3 FY27E | X2: Q4 FY27E | Y2: FY27E Total
B3: Revenue | C3: 2944 | D3: ='Revenue Build'!E19 -> 3048.6467 | E3: ='Revenue Build'!F19 -> 3472.5402 | F3: ='Revenue Build'!G19 -> 3916.4464 | G3: ='Revenue Build'!H19 -> 4373.6182 | H3: ='Revenue Build'!I19 -> 4836.0678 | I3: ='Revenue Build'!J19 -> 5333.3625 | J3: ='Revenue Build'!K19 -> 5823.8959 | K3: ='Revenue Build'!L19 -> 6296.9314 | ... M3: ='Revenue Build'!N19 -> 7146.0276 | N3: =M3*(1+$N$4) -> 7539.0592 | P3: Revenue | Q3: 751 | R3: 736 | S3: 740 | T3: 717 | U3: 773 | V3: =($Y$3-$U$3)*(R3/SUM($R$3:$T$3)) -> 763.73733 | W3: =($Y$3-$U$3)*(S3/SUM($R$3:$T$3)) -> 767.88808 | X3: =($Y$3-$U$3)*(T3/SUM($R$3:$T$3)) -> 744.02129 | Y3: ='Revenue Build'!E19 -> 3048.6467
B4: Revenue Growth | C4: 0.035 | D4: ='Revenue Build'!E20 -> 0.035545754 | E4: ='Revenue Build'!F20 -> 0.13904317 | F4: ='Revenue Build'!G20 -> 0.12783329 | G4: ='Revenue Build'!H20 -> 0.11673127 | H4: ='Revenue Build'!I20 -> 0.10573616 | I4: ='Revenue Build'!J20 -> 0.10283039 | J4: ='Revenue Build'!K20 -> 0.091974504 | K4: ='Revenue Build'!L20 -> 0.081223209 | ... M4: ='Revenue Build'!N20 -> 0.060030608 | N4: ='Inputs & Assumptions'!$B$27 -> 0.055 | P4: Revenue Growth (To same period prev year) | Q4: 0.0135 | R4: 0.0040927694 | S4: 0.051136364 | T4: 0.076576577 | U4: 0.029294274 | V4: - | W4: - | X4: - | Y4: ='Revenue Build'!E20 -> 0.035545754
B5: EBIT (Operating) margin | C5: 0.1321 | D5: ='Inputs & Assumptions'!B19 -> 0.072 | E5: ='Inputs & Assumptions'!B20 -> 0.1175 | F5: =(1+'Inputs & Assumptions'!$B$21)*EXP(0.01*(COLUMNS(Valuation!$F$5:F5)-(3+1)/2))-1 -> 0.13855731 | G5: =(1+'Inputs & Assumptions'!$B$21)*EXP(0.01*(COLUMNS(Valuation!$F$5:G5)-(3+1)/2))-1 -> 0.15 | H5: =(1+'Inputs & Assumptions'!$B$21)*EXP(0.01*(COLUMNS(Valuation!$F$5:H5)-(3+1)/2))-1 -> 0.16155769 | I5: =(1+'Inputs & Assumptions'!$B$22)*EXP(0.001*(COLUMNS(Valuation!$I$5:I5)-(5+1)/2))-1 -> 0.18762238 | J5: =(1+'Inputs & Assumptions'!$B$22)*EXP(0.001*(COLUMNS(Valuation!$I$5:J5)-(5+1)/2))-1 -> 0.18881059 | K5: =(1+'Inputs & Assumptions'!$B$22)*EXP(0.001*(COLUMNS(Valuation!$I$5:K5)-(5+1)/2))-1 -> 0.19 | L5: =(1+'Inputs & Assumptions'!$B$22)*EXP(0.001*(COLUMNS(Valuation!$I$5:L5)-(5+1)/2))-1 -> 0.1911906 | M5: =(1+'Inputs & Assumptions'!$B$22)*EXP(0.001*(COLUMNS(Valuation!$I$5:M5)-(5+1)/2))-1 -> 0.19238238 | N5: ='Inputs & Assumptions'!$B$23 -> 0.17 | P5: EBIT (Operating) margin | Q5: 0.14571238 | R5: 0.14004076 | S5: 0.12862162 | T5: 0.11288703 | U5: 0.0628 | V5: =$U$5+(COLUMNS($V:V))*(($Y$5-$U$5)*SUM($U$3:$X$3))/($V$3+2*$W$3+3*$X$3) -> 0.068989357 | W5: =$U$5+(COLUMNS($V:W))*(($Y$5-$U$5)*SUM($U$3:$X$3))/($V$3+2*$W$3+3*$X$3) -> 0.075178714 | X5: =$U$5+(COLUMNS($V:X))*(($Y$5-$U$5)*SUM($U$3:$X$3))/($V$3+2*$W$3+3*$X$3) -> 0.081368071 | Y5: ='Inputs & Assumptions'!B19 -> 0.072
B6: EBIT (Operating income) | C6: 389 | D6: =D3*D5 -> 219.50256 | E6: =E3*E5 -> 408.02347 | F6: =F3*F5 -> 542.65228 | G6: =G3*G5 -> 656.04273 | H6: =H3*H5 -> 781.30395 | I6: =I3*I5 -> 1000.6582 | J6: =J3*J5 -> 1099.6132 | K6: =K3*K5 -> 1196.417 | ... N6: =N3*N5 -> 1281.6401 | P6: EBIT (Operating income) | Q6: 109.43 | R6: 103.07 | S6: 95.18 | T6: 80.94 | U6: 48.53 | V6: =V3*V5 -> 52.689747 | W6: =W3*W5 -> 57.728838 | X6: =X3*X5 -> 60.539577 | Y6: =SUM(U6:X6) -> 219.48816
B7: Tax | C7: 0.26 | D7: ='Inputs & Assumptions'!$B$30 -> 0.26 | E7: ='Inputs & Assumptions'!$B$30 -> 0.26 | F7: ='Inputs & Assumptions'!$B$30 -> 0.26 | G7: ='Inputs & Assumptions'!$B$30 -> 0.26 | H7: ='Inputs & Assumptions'!$B$30 -> 0.26 | I7: ='Inputs & Assumptions'!$B$30 -> 0.26 | J7: ='Inputs & Assumptions'!$B$30 -> 0.26 | K7: ='Inputs & Assumptions'!$B$30 -> 0.26 | ... N7: ='Inputs & Assumptions'!$B$30 -> 0.26 | P7: Tax | Q7: - | R7: - | S7: - | T7: - | U7: 0.26 | V7: ='Inputs & Assumptions'!$B$30 -> 0.26 | W7: ='Inputs & Assumptions'!$B$30 -> 0.26 | X7: ='Inputs & Assumptions'!$B$30 -> 0.26 | Y7: ='Inputs & Assumptions'!$B$30 -> 0.26
B8: NOPAT | C8: =C6*(1-C7) -> 287.86 | D8: =D6*(1-D7) -> 162.4319 | E8: =E6*(1-E7) -> 301.93737 | F8: =F6*(1-F7) -> 401.56268 | G8: =G6*(1-G7) -> 485.47162 | H8: =H6*(1-H7) -> 578.16492 | I8: =I6*(1-I7) -> 740.48704 | J8: =J6*(1-J7) -> 813.7138 | ... N8: =N6*(1-N7) -> 948.41364 | P8: NOPAT | Q8: - | R8: - | S8: - | T8: - | U8: 48 | V8: =V6*(1-V7) -> 38.990413 | W8: =W6*(1-W7) -> 42.71934 | X8: =X6*(1-X7) -> 44.799287 | Y8: =Y6*(1-Y7) -> 162.42124
B9: Reinvestment | C9: - | D9: =D35 -> 37.821964 | E9: =E35 -> 55.618223 | F9: =F35 -> 61.323632 | G9: =G35 -> 66.897682 | H9: =H35 -> 72.201523 | I9: =I35 -> 79.103757 | J9: =J35 -> 84.22176 | K9: =K35 -> 88.706061 | ... M9: =M35 -> 95.237268 | N9: =N8*('Inputs & Assumptions'!$B$27/'Inputs & Assumptions'!$B$28) -> 372.59107 | P9: Reinvestment | Q9: - | R9: - | S9: - | T9: - | U9: =$Y$9*(U3/$Y$3) -> 9.589953 | V9: =$Y$9*(V3/$Y$3) -> 9.4750389 | W9: =$Y$9*(W3/$Y$3) -> 9.5265337 | X9: =$Y$9*(X3/$Y$3) -> 9.2304388 | Y9: =D35 -> 37.821964
B10: FCFF | C10: - | D10: =D8-D9-U10-(V10*(('Inputs & Assumptions'!$B$3-'Inputs & Assumptions'!$C$8)/('Inputs & Assumptions'!$D$8-'Inputs & Assumptions'!$C$8))) -> 62.847061 | E10: =E8-E9 -> 246.31915 | F10: =F8-F9 -> 340.23905 | G10: =G8-G9 -> 418.57394 | H10: =H8-H9 -> 505.9634 | I10: =I8-I9 -> 661.38328 | J10: =J8-J9 -> 729.49204 | K10: =K8-K9 -> 796.64249 | L10: =L8-L9 -> 861.35377 | ... N10: =N8-N9 -> 575.82257 | P10: FCFF | Q10: - | R10: - | S10: - | T10: - | U10: =U8-U9 -> 38.410047 | V10: =V8-V9 -> 29.515374 | W10: =W8-W9 -> 33.192807 | X10: =X8-X9 -> 35.568848 | Y10: =Y8-Y9 -> 124.59928
B11: Cost of Capital | C11: - | D11: ='Inputs & Assumptions'!$B$29 -> 0.10453928 | E11: ='Inputs & Assumptions'!$B$29 -> 0.10453928 | F11: ='Inputs & Assumptions'!$B$29 -> 0.10453928 | G11: ='Inputs & Assumptions'!$B$29 -> 0.10453928 | H11: ='Inputs & Assumptions'!$B$29 -> 0.10453928 | I11: ='Inputs & Assumptions'!$B$29 -> 0.10453928 | J11: ='Inputs & Assumptions'!$B$29 -> 0.10453928 | K11: ='Inputs & Assumptions'!$B$29 -> 0.10453928 | ... N11: ='Inputs & Assumptions'!$B$29 -> 0.10453928
B12: Discount Factor | C12: - | D12: =1/(1+D11)^(('Inputs & Assumptions'!$B$6-'Inputs & Assumptions'!$B$3)/365) -> 0.94671832 | E12: =D12*(1/(1+E11)) -> 0.85711603 | F12: =E12*(1/(1+F11)) -> 0.77599416 | G12: =F12*(1/(1+G11)) -> 0.70255008 | H12: =G12*(1/(1+H11)) -> 0.63605713 | I12: =H12*(1/(1+I11)) -> 0.57585741 | J12: =I12*(1/(1+J11)) -> 0.52135531 | K12: =J12*(1/(1+K11)) -> 0.47201156 | L12: =K12*(1/(1+L11)) -> 0.42733796 | M12: =L12*(1/(1+M11)) -> 0.38689249
B13: PV of FCFF | C13: - | D13: =D10*D12 -> 59.498465 | E13: =E10*E12 -> 211.12409 | F13: =F10*F12 -> 264.02352 | G13: =G10*G12 -> 294.06916 | H13: =H10*H12 -> 321.82163 | I13: =I10*I12 -> 380.86246 | J13: =J10*J12 -> 380.32455 | K13: =K10*K12 -> 376.02446 | ... M13: =M10*M12 -> 356.75063
B15: Terminal FCFF | C15: =N10 -> 575.82257
B16: Terminal Cost of Capital | C16: =N11 -> 0.10453928 | E16: Sensitivity Analysis
B17: Terminal Value | C17: =C15/(C16-N4) -> 11623.556
B18: PV of Terminal Value | C18: =C17*M12 -> 4497.0665 | E18: Value Per Share
B19: PV of FCFF next 10 years | C19: =SUM(D13:M13) -> 3012.5881
B20: Sum of PV | C20: =C18+C19 -> 7509.6546 | H20: Terminal Growth Rate
B21: - Debt | C21: ='Cost of Capital'!B22 -> 51.58 | F21: Value | G21: =C25 -> 225.32883 | H21: =I21-0.5% -> 0.045 | I21: =J21-0.5% -> 0.05 | J21: ='Inputs & Assumptions'!B27 -> 0.055 | K21: =J21+0.5% -> 0.06 | L21: =K21+0.5% -> 0.065
B22: + Cash | C22: ='Inputs & Assumptions'!B12 -> 816 | G22: =G23-0.5% -> 0.094539278 | H22: 204.7122 | I22: 214.54183 | J22: 226.35567 | K22: 240.82196 | L22: 258.94697
B23: Value of Equity | C23: =C20-C21+C22 -> 8274.0746 | G23: =G24-0.5% -> 0.099539278 | H23: 204.25122 | I23: 214.05621 | J23: 225.84044 | K23: 240.27047 | L23: 258.35004
B24: Shares Outstanding | C24: ='Inputs & Assumptions'!B10 -> 36.72 | F24: WACC | G24: ='Cost of Capital'!D34 -> 0.10453928 | H24: 203.79349 | I24: 213.57401 | J24: 225.32883 | K24: 239.72285 | L24: 257.75731
B25: Estimated value per share | C25: =C23/C24 -> 225.32883 | G25: =G24+0.5% -> 0.10953928 | H25: 203.33896 | I25: 213.09518 | J25: 224.8208 | K25: 239.17907 | L25: 257.16873
B26: Current Price | C26: ='Inputs & Assumptions'!B9 -> 195 | G26: =G25+0.5% -> 0.11453928 | H26: 202.88759 | I26: 212.61969 | J26: 224.31631 | K26: 238.63907 | L26: 256.58424
B27: Implied Upside/Downside | C27: =C25/C26-1 -> 0.15553246
B29: (Rs. Crores) | C29: 2026 | D29: 2027 | E29: =D29+1 -> 2028 | F29: =E29+1 -> 2029 | G29: =F29+1 -> 2030 | H29: =G29+1 -> 2031 | I29: =H29+1 -> 2032 | J29: =I29+1 -> 2033 | K29: =J29+1 -> 2034 | L29: =K29+1 -> 2035 | M29: =L29+1 -> 2036
B30: Gross Capex | C30: 67 | D30: =D3*'Inputs & Assumptions'!$B$24 -> 67.070227 | E30: =E3*'Inputs & Assumptions'!$B$24 -> 76.395884 | F30: =F3*'Inputs & Assumptions'!$B$24 -> 86.161821 | G30: =G3*'Inputs & Assumptions'!$B$24 -> 96.2196 | H30: =H3*'Inputs & Assumptions'!$B$24 -> 106.39349 | I30: =I3*'Inputs & Assumptions'!$B$24 -> 117.33398 | J30: =J3*'Inputs & Assumptions'!$B$24 -> 128.12571 | K30: =K3*'Inputs & Assumptions'!$B$24 -> 138.53249 | ... M30: =M3*'Inputs & Assumptions'!$B$24 -> 157.21261
B31: PP&E Depreciation | C31: 33 | D31: =D3*'Inputs & Assumptions'!$B$25 -> 33.535114 | E31: =E3*'Inputs & Assumptions'!$B$25 -> 38.197942 | F31: =F3*'Inputs & Assumptions'!$B$25 -> 43.080911 | G31: =G3*'Inputs & Assumptions'!$B$25 -> 48.1098 | H31: =H3*'Inputs & Assumptions'!$B$25 -> 53.196746 | I31: =I3*'Inputs & Assumptions'!$B$25 -> 58.666988 | J31: =J3*'Inputs & Assumptions'!$B$25 -> 64.062855 | K31: =K3*'Inputs & Assumptions'!$B$25 -> 69.266245 | ... M31: =M3*'Inputs & Assumptions'!$B$25 -> 78.606304
B32: Net Capex | C32: =C30-C31 -> 34 | D32: =D30-D31 -> 33.535114 | E32: =E30-E31 -> 38.197942 | F32: =F30-F31 -> 43.080911 | G32: =G30-G31 -> 48.1098 | H32: =H30-H31 -> 53.196746 | I32: =I30-I31 -> 58.666988 | J32: =J30-J31 -> 64.062855 | ... M32: =M30-M31 -> 78.606304
B33: NWC | C33: 121 | D33: =D3*('Inputs & Assumptions'!$B$26/365) -> 125.28685 | E33: =E3*('Inputs & Assumptions'!$B$26/365) -> 142.70713 | F33: =F3*('Inputs & Assumptions'!$B$26/365) -> 160.94985 | G33: =G3*('Inputs & Assumptions'!$B$26/365) -> 179.73773 | H33: =H3*('Inputs & Assumptions'!$B$26/365) -> 198.74251 | I33: =I3*('Inputs & Assumptions'!$B$26/365) -> 219.17928 | J33: =J3*('Inputs & Assumptions'!$B$26/365) -> 239.33819 | K33: =K3*('Inputs & Assumptions'!$B$26/365) -> 258.778 | ... M33: =M3*('Inputs & Assumptions'!$B$26/365) -> 293.67237
B34: Change in NWC | C34: - | D34: =D33-C33 -> 4.2868507 | E34: =E33-D33 -> 17.420281 | F34: =F33-E33 -> 18.242722 | G34: =G33-F33 -> 18.787881 | H34: =H33-G33 -> 19.004777 | I34: =I33-H33 -> 20.43677 | J34: =J33-I33 -> 20.158906 | K34: =K33-J33 -> 19.439816 | ... M34: =M33-L33 -> 16.630964
B35: Reinvestment | C35: - | D35: =D32+D34 -> 37.821964 | E35: =E32+E34 -> 55.618223 | F35: =F32+F34 -> 61.323632 | G35: =G32+G34 -> 66.897682 | H35: =H32+H34 -> 72.201523 | I35: =I32+I34 -> 79.103757 | J35: =J32+J34 -> 84.22176 | K35: =K32+K34 -> 88.706061 | ... M35: =M32+M34 -> 95.237268

Sheet Market Expectations
B2: Current Share Price | C2: ='Inputs & Assumptions'!B9 -> 195
B3: Shares Outstanding | C3: ='Inputs & Assumptions'!B10 -> 36.72
B4: Market Capitalization | C4: ='Inputs & Assumptions'!B11 -> 7160.4
B5: Debt | C5: ='Cost of Capital'!B22 -> 51.58
B6: Cash | C6: ='Inputs & Assumptions'!B12 -> 816
B7: Market Implied Enterprise Value | C7: =C4+C5-C6 -> 6395.98
B10: SCENARIO A: Implied Growth | O10: Scenario A: If margins and below variables remain consistent with my assumptions, how much revenue growth is required to justify the current market price?
B12: (Rs. Crores) | C12: =Valuation!D2 -> 2027 | D12: =C12+1 -> 2028 | E12: =D12+1 -> 2029 | F12: =E12+1 -> 2030 | G12: =F12+1 -> 2031 | H12: =G12+1 -> 2032 | I12: =H12+1 -> 2033 | J12: =I12+1 -> 2034 | K12: =J12+1 -> 2035 | L12: =K12+1 -> 2036 | M12: Terminal Year
B13: Revenue | C13: =Valuation!D3 -> 3048.6467 | D13: =C13*(1+$P$20) -> 3289.063 | E13: =D13*(1+$P$20) -> 3548.4385 | F13: =E13*(1+$P$20) -> 3828.2683 | G13: =F13*(1+$P$20) -> 4130.1656 | H13: =G13*(1+$P$20) -> 4455.8704 | I13: =H13*(1+$P$20) -> 4807.2604 | J13: =I13*(1+$P$20) -> 5186.3609 | K13: =J13*(1+$P$20) -> 5595.3574 | L13: =K13*(1+$P$20) -> 6036.6072 | M13: =L13*(1+M14) -> 6368.6206 | O13: Assumptions | P13: Value
B14: Revenue Growth | C14: =Valuation!D4 -> 0.035545754 | D14: =D13/C13-1 -> 0.07886 | E14: =E13/D13-1 -> 0.07886 | F14: =F13/E13-1 -> 0.07886 | G14: =G13/F13-1 -> 0.07886 | H14: =H13/G13-1 -> 0.07886 | I14: =I13/H13-1 -> 0.07886 | J14: =J13/I13-1 -> 0.07886 | K14: =K13/J13-1 -> 0.07886 | L14: =L13/K13-1 -> 0.07886 | M14: =Valuation!N4 -> 0.055 | O14: FY27 Revenue & Margin | P14: Same as Base DCF
B15: EBIT (Operating) margin | C15: =Valuation!D5 -> 0.072 | D15: =Valuation!E5 -> 0.1175 | E15: =Valuation!F5 -> 0.13855731 | F15: =Valuation!G5 -> 0.15 | G15: =Valuation!H5 -> 0.16155769 | H15: =Valuation!I5 -> 0.18762238 | I15: =Valuation!J5 -> 0.18881059 | J15: =Valuation!K5 -> 0.19 | ... M15: =Valuation!N5 -> 0.17 | O15: EBIT Margin rest of forecast years | P15: Same as Base DCF
B16: EBIT (Operating income) | C16: =C13*C15 -> 219.50256 | D16: =D13*D15 -> 386.4649 | E16: =E13*E15 -> 491.66209 | F16: =F13*F15 -> 574.24025 | G16: =G13*G15 -> 667.26002 | H16: =H13*H15 -> 836.02101 | I16: =I13*I15 -> 907.66169 | J16: =J13*J15 -> 985.40858 | ... M16: =M13*M15 -> 1082.6655 | O16: Tax Rate | P16: Same as Base DCF
B17: Tax | C17: =Valuation!D7 -> 0.26 | D17: =Valuation!E7 -> 0.26 | E17: =Valuation!F7 -> 0.26 | F17: =Valuation!G7 -> 0.26 | G17: =Valuation!H7 -> 0.26 | H17: =Valuation!I7 -> 0.26 | I17: =Valuation!J7 -> 0.26 | J17: =Valuation!K7 -> 0.26 | ... M17: =Valuation!N7 -> 0.26 | O17: Reinvestment Assumption | P17: Same Methodology
B18: NOPAT | C18: =C16*(1-C17) -> 162.4319 | D18: =D16*(1-D17) -> 285.98403 | E18: =E16*(1-E17) -> 363.82994 | F18: =F16*(1-F17) -> 424.93779 | G18: =G16*(1-G17) -> 493.77241 | H18: =H16*(1-H17) -> 618.65555 | I18: =I16*(1-I17) -> 671.66965 | J18: =J16*(1-J17) -> 729.20235 | ... M18: =M16*(1-M17) -> 801.17248 | O18: WACC | P18: Same as Base DCF
B19: Reinvestment | C19: =Valuation!D9 -> 37.821964 | D19: =((D13*'Inputs & Assumptions'!$B$24)-('Market Expectations'!D13*'Inputs & Assumptions'!$B$25))+(('Market Expectations'!D13*('Inputs & Assumptions'!$B$26/365))-Valuation!D33) -> 46.059814 | E19: =((E13*'Inputs & Assumptions'!$B$24)-('Market Expectations'!E13*'Inputs & Assumptions'!$B$25))+(('Market Expectations'!E13*('Inputs & Assumptions'!$B$26/365))-('Market Expectations'!D13*('Inputs & Assumptions'!$B$26/365))) -> 49.692091 | F19: =((F13*'Inputs & Assumptions'!$B$24)-('Market Expectations'!F13*'Inputs & Assumptions'!$B$25))+(('Market Expectations'!F13*('Inputs & Assumptions'!$B$26/365))-('Market Expectations'!E13*('Inputs & Assumptions'!$B$26/365))) -> 53.610809 | G19: =((G13*'Inputs & Assumptions'!$B$24)-('Market Expectations'!G13*'Inputs & Assumptions'!$B$25))+(('Market Expectations'!G13*('Inputs & Assumptions'!$B$26/365))-('Market Expectations'!F13*('Inputs & Assumptions'!$B$26/365))) -> 57.838557 | H19: =((H13*'Inputs & Assumptions'!$B$24)-('Market Expectations'!H13*'Inputs & Assumptions'!$B$25))+(('Market Expectations'!H13*('Inputs & Assumptions'!$B$26/365))-('Market Expectations'!G13*('Inputs & Assumptions'!$B$26/365))) -> 62.399706 | I19: =((I13*'Inputs & Assumptions'!$B$24)-('Market Expectations'!I13*'Inputs & Assumptions'!$B$25))+(('Market Expectations'!I13*('Inputs & Assumptions'!$B$26/365))-('Market Expectations'!H13*('Inputs & Assumptions'!$B$26/365))) -> 67.320547 | J19: =((J13*'Inputs & Assumptions'!$B$24)-('Market Expectations'!J13*'Inputs & Assumptions'!$B$25))+(('Market Expectations'!J13*('Inputs & Assumptions'!$B$26/365))-('Market Expectations'!I13*('Inputs & Assumptions'!$B$26/365))) -> 72.629445 | K19: =((K13*'Inputs & Assumptions'!$B$24)-('Market Expectations'!K13*'Inputs & Assumptions'!$B$25))+(('Market Expectations'!K13*('Inputs & Assumptions'!$B$26/365))-('Market Expectations'!J13*('Inputs & Assumptions'!$B$26/365))) -> 78.357003 | L19: =((L13*'Inputs & Assumptions'!$B$24)-('Market Expectations'!L13*'Inputs & Assumptions'!$B$25))+(('Market Expectations'!L13*('Inputs & Assumptions'!$B$26/365))-('Market Expectations'!K13*('Inputs & Assumptions'!$B$26/365))) -> 84.536237 | M19: =M18*('Inputs & Assumptions'!$B$27/'Inputs & Assumptions'!$B$28) -> 314.74633 | O19: Terminal Growth & Margin | P19: Same as Base DCF
B20: FCFF | C20: =Valuation!D10 -> 62.847061 | D20: =D18-D19 -> 239.92421 | E20: =E18-E19 -> 314.13785 | F20: =F18-F19 -> 371.32698 | G20: =G18-G19 -> 435.93386 | H20: =H18-H19 -> 556.25584 | I20: =I18-I19 -> 604.34911 | J20: =J18-J19 -> 656.5729 | K20: =K18-K19 -> 713.27998 | ... M20: =M18-M19 -> 486.42615 | O20: Implied Revenue Growth (Years 2-10) | P20: 0.07886
B21: Cost of Capital | C21: =Valuation!D11 -> 0.10453928 | D21: =Valuation!E11 -> 0.10453928 | E21: =Valuation!F11 -> 0.10453928 | F21: =Valuation!G11 -> 0.10453928 | G21: =Valuation!H11 -> 0.10453928 | H21: =Valuation!I11 -> 0.10453928 | I21: =Valuation!J11 -> 0.10453928 | J21: =Valuation!K11 -> 0.10453928 | ... M21: =Valuation!N11 -> 0.10453928
B22: Discount Factor | C22: =Valuation!D12 -> 0.94671832 | D22: =C22*(1/(1+D21)) -> 0.85711603 | E22: =D22*(1/(1+E21)) -> 0.77599416 | F22: =E22*(1/(1+F21)) -> 0.70255008 | G22: =F22*(1/(1+G21)) -> 0.63605713 | H22: =G22*(1/(1+H21)) -> 0.57585741 | I22: =H22*(1/(1+I21)) -> 0.52135531 | J22: =I22*(1/(1+J21)) -> 0.47201156 | K22: =J22*(1/(1+K21)) -> 0.42733796 | L22: =K22*(1/(1+L21)) -> 0.38689249
B23: PV of FCFF | C23: =C20*C22 -> 59.498465 | D23: =D20*D22 -> 205.64289 | E23: =E20*E22 -> 243.76914 | F23: =F20*F22 -> 260.8758 | G23: =G20*G22 -> 277.27884 | H23: =H20*H22 -> 320.32405 | I23: =I20*I22 -> 315.08061 | J23: =J20*J22 -> 309.91 | ... L23: =L20*L22 -> 299.78483
B25: Terminal FCFF | C25: =M20 -> 486.42615
B26: Terminal Cost of Capital | C26: =M21 -> 0.10453928
B27: Terminal Value | C27: =C25/(C26-M14) -> 9818.9995
B28: PV of Terminal Value | C28: =C27*L22 -> 3798.8972
B29: PV of FCFF next 10 years | C29: =SUM(C23:L23) -> 2596.9762
B30: Total EV | C30: =C28+C29 -> 6395.8734
B33: SCENARIO B: Implied Margin | O33: Scenario B: Given my revenue forecast and below assumptions, what EBIT margin does the market price imply?
B35: (Rs. Crores) | C35: =Valuation!D2 -> 2027 | D35: =C35+1 -> 2028 | E35: =D35+1 -> 2029 | F35: =E35+1 -> 2030 | G35: =F35+1 -> 2031 | H35: =G35+1 -> 2032 | I35: =H35+1 -> 2033 | J35: =I35+1 -> 2034 | K35: =J35+1 -> 2035 | L35: =K35+1 -> 2036 | M35: Terminal Year
B36: Revenue | C36: =Valuation!D3 -> 3048.6467 | D36: =Valuation!E3 -> 3472.5402 | E36: =Valuation!F3 -> 3916.4464 | F36: =Valuation!G3 -> 4373.6182 | G36: =Valuation!H3 -> 4836.0678 | H36: =Valuation!I3 -> 5333.3625 | I36: =Valuation!J3 -> 5823.8959 | J36: =Valuation!K3 -> 6296.9314 | ... L36: =Valuation!M3 -> 7146.0276 | M36: =L36*(1+M37) -> 7539.0592 | O36: Assumptions | P36: Value
B37: Revenue Growth | C37: =Valuation!D4 -> 0.035545754 | D37: =Valuation!E4 -> 0.13904317 | E37: =Valuation!F4 -> 0.12783329 | F37: =Valuation!G4 -> 0.11673127 | G37: =Valuation!H4 -> 0.10573616 | H37: =Valuation!I4 -> 0.10283039 | I37: =Valuation!J4 -> 0.091974504 | J37: =Valuation!K4 -> 0.081223209 | ... M37: =Valuation!N4 -> 0.055 | O37: FY27 Revenue & Margin | P37: Same as Base DCF
B38: EBIT (Operating) margin | C38: =Valuation!D5 -> 0.072 | D38: =$P$43 -> 0.11235 | E38: =$P$43 -> 0.11235 | F38: =$P$43 -> 0.11235 | G38: =$P$43 -> 0.11235 | H38: =$P$43 -> 0.11235 | I38: =$P$43 -> 0.11235 | J38: =$P$43 -> 0.11235 | K38: =$P$43 -> 0.11235 | L38: =$P$43 -> 0.11235 | M38: =Valuation!N5 -> 0.17 | O38: Revenue Growth rest of forecast years | P38: Same as Base DCF
B39: EBIT (Operating income) | C39: =C36*C38 -> 219.50256 | D39: =D36*D38 -> 390.13989 | E39: =E36*E38 -> 440.01276 | F39: =F36*F38 -> 491.37601 | G39: =G36*G38 -> 543.33222 | H39: =H36*H38 -> 599.20328 | I39: =I36*I38 -> 654.3147 | J39: =J36*J38 -> 707.46024 | ... M39: =M36*M38 -> 1281.6401 | O39: Tax Rate | P39: Same as Base DCF
B40: Tax | C40: =Valuation!D7 -> 0.26 | D40: =Valuation!E7 -> 0.26 | E40: =Valuation!F7 -> 0.26 | F40: =Valuation!G7 -> 0.26 | G40: =Valuation!H7 -> 0.26 | H40: =Valuation!I7 -> 0.26 | I40: =Valuation!J7 -> 0.26 | J40: =Valuation!K7 -> 0.26 | ... M40: =Valuation!N7 -> 0.26 | O40: Reinvestment Assumption | P40: Same Methodology
B41: NOPAT | C41: =C39*(1-C40) -> 162.4319 | D41: =D39*(1-D40) -> 288.70352 | E41: =E39*(1-E40) -> 325.60944 | F41: =F39*(1-F40) -> 363.61824 | G41: =G39*(1-G40) -> 402.06584 | H41: =H39*(1-H40) -> 443.41043 | I41: =I39*(1-I40) -> 484.19288 | J41: =J39*(1-J40) -> 523.52058 | ... M41: =M39*(1-M40) -> 948.41364 | O41: WACC | P41: Same as Base DCF
B42: Reinvestment | C42: =Valuation!D9 -> 37.821964 | D42: =((D36*'Inputs & Assumptions'!$B$24)-('Market Expectations'!D36*'Inputs & Assumptions'!$B$25))+(('Market Expectations'!D36*('Inputs & Assumptions'!$B$26/365))-Valuation!D33) -> 55.618223 | E42: =((E36*'Inputs & Assumptions'!$B$24)-('Market Expectations'!E36*'Inputs & Assumptions'!$B$25))+(('Market Expectations'!E36*('Inputs & Assumptions'!$B$26/365))-('Market Expectations'!D36*('Inputs & Assumptions'!$B$26/365))) -> 61.323632 | F42: =((F36*'Inputs & Assumptions'!$B$24)-('Market Expectations'!F36*'Inputs & Assumptions'!$B$25))+(('Market Expectations'!F36*('Inputs & Assumptions'!$B$26/365))-('Market Expectations'!E36*('Inputs & Assumptions'!$B$26/365))) -> 66.897682 | G42: =((G36*'Inputs & Assumptions'!$B$24)-('Market Expectations'!G36*'Inputs & Assumptions'!$B$25))+(('Market Expectations'!G36*('Inputs & Assumptions'!$B$26/365))-('Market Expectations'!F36*('Inputs & Assumptions'!$B$26/365))) -> 72.201523 | H42: =((H36*'Inputs & Assumptions'!$B$24)-('Market Expectations'!H36*'Inputs & Assumptions'!$B$25))+(('Market Expectations'!H36*('Inputs & Assumptions'!$B$26/365))-('Market Expectations'!G36*('Inputs & Assumptions'!$B$26/365))) -> 79.103757 | I42: =((I36*'Inputs & Assumptions'!$B$24)-('Market Expectations'!I36*'Inputs & Assumptions'!$B$25))+(('Market Expectations'!I36*('Inputs & Assumptions'!$B$26/365))-('Market Expectations'!H36*('Inputs & Assumptions'!$B$26/365))) -> 84.22176 | J42: =((J36*'Inputs & Assumptions'!$B$24)-('Market Expectations'!J36*'Inputs & Assumptions'!$B$25))+(('Market Expectations'!J36*('Inputs & Assumptions'!$B$26/365))-('Market Expectations'!I36*('Inputs & Assumptions'!$B$26/365))) -> 88.706061 | K42: =((K36*'Inputs & Assumptions'!$B$24)-('Market Expectations'!K36*'Inputs & Assumptions'!$B$25))+(('Market Expectations'!K36*('Inputs & Assumptions'!$B$26/365))-('Market Expectations'!J36*('Inputs & Assumptions'!$B$26/365))) -> 92.418151 | L42: =((L36*'Inputs & Assumptions'!$B$24)-('Market Expectations'!L36*'Inputs & Assumptions'!$B$25))+(('Market Expectations'!L36*('Inputs & Assumptions'!$B$26/365))-('Market Expectations'!K36*('Inputs & Assumptions'!$B$26/365))) -> 95.237268 | M42: =M41*('Inputs & Assumptions'!$B$27/'Inputs & Assumptions'!$B$28) -> 372.59107 | O42: Terminal Growth & Margin | P42: Same as Base DCF
B43: FCFF | C43: =Valuation!D10 -> 62.847061 | D43: =D41-D42 -> 233.0853 | E43: =E41-E42 -> 264.28581 | F43: =F41-F42 -> 296.72056 | G43: =G41-G42 -> 329.86432 | H43: =H41-H42 -> 364.30667 | I43: =I41-I42 -> 399.97112 | J43: =J41-J42 -> 434.81452 | K43: =K41-K42 -> 468.05019 | ... M43: =M41-M42 -> 575.82257 | O43: Implied Margin (Years 2-10) | P43: 0.11235
B44: Cost of Capital | C44: =Valuation!D11 -> 0.10453928 | D44: =Valuation!E11 -> 0.10453928 | E44: =Valuation!F11 -> 0.10453928 | F44: =Valuation!G11 -> 0.10453928 | G44: =Valuation!H11 -> 0.10453928 | H44: =Valuation!I11 -> 0.10453928 | I44: =Valuation!J11 -> 0.10453928 | J44: =Valuation!K11 -> 0.10453928 | ... M44: =Valuation!N11 -> 0.10453928
B45: Discount Factor | C45: =Valuation!D12 -> 0.94671832 | D45: =C45*(1/(1+D44)) -> 0.85711603 | E45: =D45*(1/(1+E44)) -> 0.77599416 | F45: =E45*(1/(1+F44)) -> 0.70255008 | G45: =F45*(1/(1+G44)) -> 0.63605713 | H45: =G45*(1/(1+H44)) -> 0.57585741 | I45: =H45*(1/(1+I44)) -> 0.52135531 | J45: =I45*(1/(1+J44)) -> 0.47201156 | K45: =J45*(1/(1+K44)) -> 0.42733796 | L45: =K45*(1/(1+L44)) -> 0.38689249
B46: PV of FCFF | C46: =C43*C45 -> 59.498465 | D46: =D43*D45 -> 199.78114 | E46: =E43*E45 -> 205.08424 | F46: =F43*F45 -> 208.46106 | G46: =G43*G45 -> 209.81255 | H46: =H43*H45 -> 209.7887 | I46: =I43*I45 -> 208.52707 | J46: =J43*J45 -> 205.23748 | ... L46: =L43*L45 -> 193.01151
B48: Terminal FCFF | C48: =M43 -> 575.82257
B49: Terminal Cost of Capital | C49: =M44 -> 0.10453928
...
